<robot name = "robot">
    <link name="root">
        <inertial>
            <origin xyz="0 0 2.0" rpy="0 0 0"/>
            <mass value="1" />
            <inertia ixx="100" ixy="0" ixz="0" iyy="100" iyz="0" izz="100" />
        </inertial>
        <visual>
            <origin xyz="0 0 2.0" rpy="0 0 0"/>
            <geometry>
                <box size="0.7634271049907806 0.6173534887046259 0.9342220466702944" />
            </geometry>
            <material name="0 1 0 1">
                <color rgba="0 1 0 1"/>
            </material>
        </visual>
        <collision>
            <origin xyz="0 0 2.0" rpy="0 0 0"/>
            <geometry>
                <box size="0.7634271049907806 0.6173534887046259 0.9342220466702944" />
            </geometry>
        </collision>
    </link>
    <link name="0">
        <inertial>
            <origin xyz="-0.4982013635990527 0.0 0.0" rpy="0 0 0"/>
            <mass value="1" />
            <inertia ixx="100" ixy="0" ixz="0" iyy="100" iyz="0" izz="100" />
        </inertial>
        <visual>
            <origin xyz="-0.4982013635990527 0.0 0.0" rpy="0 0 0"/>
            <geometry>
                <box size="0.9964027271981054 0.9628027407039228 0.8374351913517831" />
            </geometry>
            <material name="0 0 1 1">
                <color rgba="0 0 1 1"/>
            </material>
        </visual>
        <collision>
            <origin xyz="-0.4982013635990527 0.0 0.0" rpy="0 0 0"/>
            <geometry>
                <box size="0.9964027271981054 0.9628027407039228 0.8374351913517831" />
            </geometry>
        </collision>
    </link>
    <link name="1">
        <inertial>
            <origin xyz="0.0 0.0 -0.38733164532998454" rpy="0 0 0"/>
            <mass value="1" />
            <inertia ixx="100" ixy="0" ixz="0" iyy="100" iyz="0" izz="100" />
        </inertial>
        <visual>
            <origin xyz="0.0 0.0 -0.38733164532998454" rpy="0 0 0"/>
            <geometry>
                <box size="0.800938624422185 0.8912577213701942 0.7746632906599691" />
            </geometry>
            <material name="0 1 0 1">
                <color rgba="0 1 0 1"/>
            </material>
        </visual>
        <collision>
            <origin xyz="0.0 0.0 -0.38733164532998454" rpy="0 0 0"/>
            <geometry>
                <box size="0.800938624422185 0.8912577213701942 0.7746632906599691" />
            </geometry>
        </collision>
    </link>
    <link name="3">
        <inertial>
            <origin xyz="0.0 0.3925974543012574 0.0" rpy="0 0 0"/>
            <mass value="1" />
            <inertia ixx="100" ixy="0" ixz="0" iyy="100" iyz="0" izz="100" />
        </inertial>
        <visual>
            <origin xyz="0.0 0.3925974543012574 0.0" rpy="0 0 0"/>
            <geometry>
                <box size="0.6850907888847471 0.7851949086025148 0.7096083993455649" />
            </geometry>
            <material name="0 0 1 1">
                <color rgba="0 0 1 1"/>
            </material>
        </visual>
        <collision>
            <origin xyz="0.0 0.3925974543012574 0.0" rpy="0 0 0"/>
            <geometry>
                <box size="0.6850907888847471 0.7851949086025148 0.7096083993455649" />
            </geometry>
        </collision>
    </link>
    <link name="4">
        <inertial>
            <origin xyz="0.0 0.40448089952809757 0.0" rpy="0 0 0"/>
            <mass value="1" />
            <inertia ixx="100" ixy="0" ixz="0" iyy="100" iyz="0" izz="100" />
        </inertial>
        <visual>
            <origin xyz="0.0 0.40448089952809757 0.0" rpy="0 0 0"/>
            <geometry>
                <box size="0.789948181979392 0.8089617990561951 0.6353355574300554" />
            </geometry>
            <material name="0 1 0 1">
                <color rgba="0 1 0 1"/>
            </material>
        </visual>
        <collision>
            <origin xyz="0.0 0.40448089952809757 0.0" rpy="0 0 0"/>
            <geometry>
                <box size="0.789948181979392 0.8089617990561951 0.6353355574300554" />
            </geometry>
        </collision>
    </link>
    <joint name="root_0" type="revolute">
       <parent link="root"/>
       <child  link="0"/>
       <origin rpy="0 0 0" xyz="-0.3817135524953903 0.0 2.0" />
     <axis xyz="0 0 1"/>
       <limit effort="0.0" lower="-3.14159" upper="3.14159" velocity="0.0"/>
    </joint>
    <joint name="0_1" type="revolute">
       <parent link="0"/>
       <child  link="1"/>
       <origin rpy="0 0 0" xyz="-0.4982013635990527 0.0 -0.41871759567589156" />
     <axis xyz="0 1 0"/>
       <limit effort="0.0" lower="-3.14159" upper="3.14159" velocity="0.0"/>
    </joint>
    <joint name="0_3" type="revolute">
       <parent link="0"/>
       <child  link="3"/>
       <origin rpy="0 0 0" xyz="-0.4982013635990527 0.4814013703519614 0.0" />
     <axis xyz="0 1 0"/>
       <limit effort="0.0" lower="-3.14159" upper="3.14159" velocity="0.0"/>
    </joint>
    <joint name="3_4" type="revolute">
       <parent link="3"/>
       <child  link="4"/>
       <origin rpy="0 0 0" xyz="0.0 0.7851949086025148 0.0" />
     <axis xyz="0 1 0"/>
       <limit effort="0.0" lower="-3.14159" upper="3.14159" velocity="0.0"/>
    </joint>
</robot>