<robot name = "robot">
    <link name="root">
        <inertial>
            <origin xyz="0 0 2.0" rpy="0 0 0"/>
            <mass value="1" />
            <inertia ixx="100" ixy="0" ixz="0" iyy="100" iyz="0" izz="100" />
        </inertial>
        <visual>
            <origin xyz="0 0 2.0" rpy="0 0 0"/>
            <geometry>
                <box size="0.9525889626595079 0.9128809533429603 0.627328542582006" />
            </geometry>
            <material name="0 0 1 1">
                <color rgba="0 0 1 1"/>
            </material>
        </visual>
        <collision>
            <origin xyz="0 0 2.0" rpy="0 0 0"/>
            <geometry>
                <box size="0.9525889626595079 0.9128809533429603 0.627328542582006" />
            </geometry>
        </collision>
    </link>
    <link name="0">
        <inertial>
            <origin xyz="0.0 0.0 -0.32373975011654055" rpy="0 0 0"/>
            <mass value="1" />
            <inertia ixx="100" ixy="0" ixz="0" iyy="100" iyz="0" izz="100" />
        </inertial>
        <visual>
            <origin xyz="0.0 0.0 -0.32373975011654055" rpy="0 0 0"/>
            <geometry>
                <box size="0.6482045105476706 0.6694653574255502 0.6474795002330811" />
            </geometry>
            <material name="0 1 0 1">
                <color rgba="0 1 0 1"/>
            </material>
        </visual>
        <collision>
            <origin xyz="0.0 0.0 -0.32373975011654055" rpy="0 0 0"/>
            <geometry>
                <box size="0.6482045105476706 0.6694653574255502 0.6474795002330811" />
            </geometry>
        </collision>
    </link>
    <link name="1">
        <inertial>
            <origin xyz="-0.45575523177259264 0.0 0.0" rpy="0 0 0"/>
            <mass value="1" />
            <inertia ixx="100" ixy="0" ixz="0" iyy="100" iyz="0" izz="100" />
        </inertial>
        <visual>
            <origin xyz="-0.45575523177259264 0.0 0.0" rpy="0 0 0"/>
            <geometry>
                <box size="0.9115104635451853 0.9153476039226043 0.5537964581797001" />
            </geometry>
            <material name="0 0 1 1">
                <color rgba="0 0 1 1"/>
            </material>
        </visual>
        <collision>
            <origin xyz="-0.45575523177259264 0.0 0.0" rpy="0 0 0"/>
            <geometry>
                <box size="0.9115104635451853 0.9153476039226043 0.5537964581797001" />
            </geometry>
        </collision>
    </link>
    <link name="2">
        <inertial>
            <origin xyz="0.35149036298926056 0.0 0.0" rpy="0 0 0"/>
            <mass value="1" />
            <inertia ixx="100" ixy="0" ixz="0" iyy="100" iyz="0" izz="100" />
        </inertial>
        <visual>
            <origin xyz="0.35149036298926056 0.0 0.0" rpy="0 0 0"/>
            <geometry>
                <box size="0.7029807259785211 0.7963582992683782 0.8261248961658333" />
            </geometry>
            <material name="0 1 0 1">
                <color rgba="0 1 0 1"/>
            </material>
        </visual>
        <collision>
            <origin xyz="0.35149036298926056 0.0 0.0" rpy="0 0 0"/>
            <geometry>
                <box size="0.7029807259785211 0.7963582992683782 0.8261248961658333" />
            </geometry>
        </collision>
    </link>
    <link name="4">
        <inertial>
            <origin xyz="0.0 0.0 -0.27057592223636606" rpy="0 0 0"/>
            <mass value="1" />
            <inertia ixx="100" ixy="0" ixz="0" iyy="100" iyz="0" izz="100" />
        </inertial>
        <visual>
            <origin xyz="0.0 0.0 -0.27057592223636606" rpy="0 0 0"/>
            <geometry>
                <box size="0.6047645029343117 0.6021533893767133 0.5411518444727321" />
            </geometry>
            <material name="0 1 0 1">
                <color rgba="0 1 0 1"/>
            </material>
        </visual>
        <collision>
            <origin xyz="0.0 0.0 -0.27057592223636606" rpy="0 0 0"/>
            <geometry>
                <box size="0.6047645029343117 0.6021533893767133 0.5411518444727321" />
            </geometry>
        </collision>
    </link>
    <link name="5">
        <inertial>
            <origin xyz="0.0 0.40792949573549336 0.0" rpy="0 0 0"/>
            <mass value="1" />
            <inertia ixx="100" ixy="0" ixz="0" iyy="100" iyz="0" izz="100" />
        </inertial>
        <visual>
            <origin xyz="0.0 0.40792949573549336 0.0" rpy="0 0 0"/>
            <geometry>
                <box size="0.8292926386140498 0.8158589914709867 0.952296386668839" />
            </geometry>
            <material name="0 0 1 1">
                <color rgba="0 0 1 1"/>
            </material>
        </visual>
        <collision>
            <origin xyz="0.0 0.40792949573549336 0.0" rpy="0 0 0"/>
            <geometry>
                <box size="0.8292926386140498 0.8158589914709867 0.952296386668839" />
            </geometry>
        </collision>
    </link>
    <joint name="root_0" type="revolute">
       <parent link="root"/>
       <child  link="0"/>
       <origin rpy="0 0 0" xyz="0.0 0.0 1.686335728708997" />
     <axis xyz="1 0 0"/>
       <limit effort="0.0" lower="-3.14159" upper="3.14159" velocity="0.0"/>
    </joint>
    <joint name="root_1" type="revolute">
       <parent link="root"/>
       <child  link="1"/>
       <origin rpy="0 0 0" xyz="-0.47629448132975394 0.0 2.0" />
     <axis xyz="0 1 0"/>
       <limit effort="0.0" lower="-3.14159" upper="3.14159" velocity="0.0"/>
    </joint>
    <joint name="root_2" type="revolute">
       <parent link="root"/>
       <child  link="2"/>
       <origin rpy="0 0 0" xyz="0.47629448132975394 0.0 2.0" />
     <axis xyz="0 1 0"/>
       <limit effort="0.0" lower="-3.14159" upper="3.14159" velocity="0.0"/>
    </joint>
    <joint name="1_4" type="revolute">
       <parent link="1"/>
       <child  link="4"/>
       <origin rpy="0 0 0" xyz="-0.45575523177259264 0.0 -0.27689822908985007" />
     <axis xyz="0 1 0"/>
       <limit effort="0.0" lower="-3.14159" upper="3.14159" velocity="0.0"/>
    </joint>
    <joint name="1_5" type="revolute">
       <parent link="1"/>
       <child  link="5"/>
       <origin rpy="0 0 0" xyz="-0.45575523177259264 0.45767380196130214 0.0" />
     <axis xyz="0 0 1"/>
       <limit effort="0.0" lower="-3.14159" upper="3.14159" velocity="0.0"/>
    </joint>
</robot>