<robot name = "robot">
    <link name="root">
        <inertial>
            <origin xyz="0 0 2.0" rpy="0 0 0"/>
            <mass value="1" />
            <inertia ixx="100" ixy="0" ixz="0" iyy="100" iyz="0" izz="100" />
        </inertial>
        <visual>
            <origin xyz="0 0 2.0" rpy="0 0 0"/>
            <geometry>
                <box size="0.992289889480353 0.5947090110218769 0.9825939958965214" />
            </geometry>
            <material name="0 0 1 1">
                <color rgba="0 0 1 1"/>
            </material>
        </visual>
        <collision>
            <origin xyz="0 0 2.0" rpy="0 0 0"/>
            <geometry>
                <box size="0.992289889480353 0.5947090110218769 0.9825939958965214" />
            </geometry>
        </collision>
    </link>
    <link name="0">
        <inertial>
            <origin xyz="0.41317884210642386 0.0 0.0" rpy="0 0 0"/>
            <mass value="1" />
            <inertia ixx="100" ixy="0" ixz="0" iyy="100" iyz="0" izz="100" />
        </inertial>
        <visual>
            <origin xyz="0.41317884210642386 0.0 0.0" rpy="0 0 0"/>
            <geometry>
                <box size="0.8263576842128477 0.5643658022982738 0.8859635730365242" />
            </geometry>
            <material name="0 1 0 1">
                <color rgba="0 1 0 1"/>
            </material>
        </visual>
        <collision>
            <origin xyz="0.41317884210642386 0.0 0.0" rpy="0 0 0"/>
            <geometry>
                <box size="0.8263576842128477 0.5643658022982738 0.8859635730365242" />
            </geometry>
        </collision>
    </link>
    <link name="1">
        <inertial>
            <origin xyz="0.0 -0.33604908973256703 0.0" rpy="0 0 0"/>
            <mass value="1" />
            <inertia ixx="100" ixy="0" ixz="0" iyy="100" iyz="0" izz="100" />
        </inertial>
        <visual>
            <origin xyz="0.0 -0.33604908973256703 0.0" rpy="0 0 0"/>
            <geometry>
                <box size="0.5611061891184916 0.6720981794651341 0.5351739398426039" />
            </geometry>
            <material name="0 0 1 1">
                <color rgba="0 0 1 1"/>
            </material>
        </visual>
        <collision>
            <origin xyz="0.0 -0.33604908973256703 0.0" rpy="0 0 0"/>
            <geometry>
                <box size="0.5611061891184916 0.6720981794651341 0.5351739398426039" />
            </geometry>
        </collision>
    </link>
    <link name="2">
        <inertial>
            <origin xyz="0.0 -0.33008857253765306 0.0" rpy="0 0 0"/>
            <mass value="1" />
            <inertia ixx="100" ixy="0" ixz="0" iyy="100" iyz="0" izz="100" />
        </inertial>
        <visual>
            <origin xyz="0.0 -0.33008857253765306 0.0" rpy="0 0 0"/>
            <geometry>
                <box size="0.6774096743608244 0.6601771450753061 0.7758689853108538" />
            </geometry>
            <material name="0 0 1 1">
                <color rgba="0 0 1 1"/>
            </material>
        </visual>
        <collision>
            <origin xyz="0.0 -0.33008857253765306 0.0" rpy="0 0 0"/>
            <geometry>
                <box size="0.6774096743608244 0.6601771450753061 0.7758689853108538" />
            </geometry>
        </collision>
    </link>
    <link name="3">
        <inertial>
            <origin xyz="0.0 -0.2556104385896699 0.0" rpy="0 0 0"/>
            <mass value="1" />
            <inertia ixx="100" ixy="0" ixz="0" iyy="100" iyz="0" izz="100" />
        </inertial>
        <visual>
            <origin xyz="0.0 -0.2556104385896699 0.0" rpy="0 0 0"/>
            <geometry>
                <box size="0.7078205027602108 0.5112208771793398 0.6569921640234733" />
            </geometry>
            <material name="0 1 0 1">
                <color rgba="0 1 0 1"/>
            </material>
        </visual>
        <collision>
            <origin xyz="0.0 -0.2556104385896699 0.0" rpy="0 0 0"/>
            <geometry>
                <box size="0.7078205027602108 0.5112208771793398 0.6569921640234733" />
            </geometry>
        </collision>
    </link>
    <link name="4">
        <inertial>
            <origin xyz="-0.41284134049946697 0.0 0.0" rpy="0 0 0"/>
            <mass value="1" />
            <inertia ixx="100" ixy="0" ixz="0" iyy="100" iyz="0" izz="100" />
        </inertial>
        <visual>
            <origin xyz="-0.41284134049946697 0.0 0.0" rpy="0 0 0"/>
            <geometry>
                <box size="0.8256826809989339 0.9072500853883023 0.9611612404264482" />
            </geometry>
            <material name="0 1 0 1">
                <color rgba="0 1 0 1"/>
            </material>
        </visual>
        <collision>
            <origin xyz="-0.41284134049946697 0.0 0.0" rpy="0 0 0"/>
            <geometry>
                <box size="0.8256826809989339 0.9072500853883023 0.9611612404264482" />
            </geometry>
        </collision>
    </link>
    <link name="5">
        <inertial>
            <origin xyz="0.0 -0.4136997968901045 0.0" rpy="0 0 0"/>
            <mass value="1" />
            <inertia ixx="100" ixy="0" ixz="0" iyy="100" iyz="0" izz="100" />
        </inertial>
        <visual>
            <origin xyz="0.0 -0.4136997968901045 0.0" rpy="0 0 0"/>
            <geometry>
                <box size="0.892146001174813 0.827399593780209 0.7812330823380066" />
            </geometry>
            <material name="0 0 1 1">
                <color rgba="0 0 1 1"/>
            </material>
        </visual>
        <collision>
            <origin xyz="0.0 -0.4136997968901045 0.0" rpy="0 0 0"/>
            <geometry>
                <box size="0.892146001174813 0.827399593780209 0.7812330823380066" />
            </geometry>
        </collision>
    </link>
    <link name="7">
        <inertial>
            <origin xyz="0.0 0.0 -0.35389293017915896" rpy="0 0 0"/>
            <mass value="1" />
            <inertia ixx="100" ixy="0" ixz="0" iyy="100" iyz="0" izz="100" />
        </inertial>
        <visual>
            <origin xyz="0.0 0.0 -0.35389293017915896" rpy="0 0 0"/>
            <geometry>
                <box size="0.5449975515163485 0.5734379078612857 0.7077858603583179" />
            </geometry>
            <material name="0 1 0 1">
                <color rgba="0 1 0 1"/>
            </material>
        </visual>
        <collision>
            <origin xyz="0.0 0.0 -0.35389293017915896" rpy="0 0 0"/>
            <geometry>
                <box size="0.5449975515163485 0.5734379078612857 0.7077858603583179" />
            </geometry>
        </collision>
    </link>
    <link name="11">
        <inertial>
            <origin xyz="0.0 0.4461887341439173 0.0" rpy="0 0 0"/>
            <mass value="1" />
            <inertia ixx="100" ixy="0" ixz="0" iyy="100" iyz="0" izz="100" />
        </inertial>
        <visual>
            <origin xyz="0.0 0.4461887341439173 0.0" rpy="0 0 0"/>
            <geometry>
                <box size="0.8568440456602507 0.8923774682878346 0.6905221874139255" />
            </geometry>
            <material name="0 1 0 1">
                <color rgba="0 1 0 1"/>
            </material>
        </visual>
        <collision>
            <origin xyz="0.0 0.4461887341439173 0.0" rpy="0 0 0"/>
            <geometry>
                <box size="0.8568440456602507 0.8923774682878346 0.6905221874139255" />
            </geometry>
        </collision>
    </link>
    <link name="12">
        <inertial>
            <origin xyz="0.3714927698325195 0.0 0.0" rpy="0 0 0"/>
            <mass value="1" />
            <inertia ixx="100" ixy="0" ixz="0" iyy="100" iyz="0" izz="100" />
        </inertial>
        <visual>
            <origin xyz="0.3714927698325195 0.0 0.0" rpy="0 0 0"/>
            <geometry>
                <box size="0.742985539665039 0.8115690588692233 0.6811177676739513" />
            </geometry>
            <material name="0 1 0 1">
                <color rgba="0 1 0 1"/>
            </material>
        </visual>
        <collision>
            <origin xyz="0.3714927698325195 0.0 0.0" rpy="0 0 0"/>
            <geometry>
                <box size="0.742985539665039 0.8115690588692233 0.6811177676739513" />
            </geometry>
        </collision>
    </link>
    <joint name="root_0" type="revolute">
       <parent link="root"/>
       <child  link="0"/>
       <origin rpy="0 0 0" xyz="0.4961449447401765 0.0 2.0" />
     <axis xyz="1 0 0"/>
       <limit effort="0.0" lower="-3.14159" upper="3.14159" velocity="0.0"/>
    </joint>
    <joint name="root_1" type="revolute">
       <parent link="root"/>
       <child  link="1"/>
       <origin rpy="0 0 0" xyz="0.0 -0.29735450551093845 2.0" />
     <axis xyz="1 0 0"/>
       <limit effort="0.0" lower="-3.14159" upper="3.14159" velocity="0.0"/>
    </joint>
    <joint name="0_2" type="revolute">
       <parent link="0"/>
       <child  link="2"/>
       <origin rpy="0 0 0" xyz="0.41317884210642386 -0.2821829011491369 0.0" />
     <axis xyz="0 0 1"/>
       <limit effort="0.0" lower="-3.14159" upper="3.14159" velocity="0.0"/>
    </joint>
    <joint name="2_3" type="revolute">
       <parent link="2"/>
       <child  link="3"/>
       <origin rpy="0 0 0" xyz="0.0 -0.6601771450753061 0.0" />
     <axis xyz="0 1 0"/>
       <limit effort="0.0" lower="-3.14159" upper="3.14159" velocity="0.0"/>
    </joint>
    <joint name="root_4" type="revolute">
       <parent link="root"/>
       <child  link="4"/>
       <origin rpy="0 0 0" xyz="-0.4961449447401765 0.0 2.0" />
     <axis xyz="0 1 0"/>
       <limit effort="0.0" lower="-3.14159" upper="3.14159" velocity="0.0"/>
    </joint>
    <joint name="1_5" type="revolute">
       <parent link="1"/>
       <child  link="5"/>
       <origin rpy="0 0 0" xyz="0.0 -0.6720981794651341 0.0" />
     <axis xyz="0 0 1"/>
       <limit effort="0.0" lower="-3.14159" upper="3.14159" velocity="0.0"/>
    </joint>
    <joint name="root_7" type="revolute">
       <parent link="root"/>
       <child  link="7"/>
       <origin rpy="0 0 0" xyz="0.0 0.0 1.5087030020517394" />
     <axis xyz="1 0 0"/>
       <limit effort="0.0" lower="-3.14159" upper="3.14159" velocity="0.0"/>
    </joint>
    <joint name="4_11" type="revolute">
       <parent link="4"/>
       <child  link="11"/>
       <origin rpy="0 0 0" xyz="-0.41284134049946697 0.45362504269415116 0.0" />
     <axis xyz="0 1 0"/>
       <limit effort="0.0" lower="-3.14159" upper="3.14159" velocity="0.0"/>
    </joint>
    <joint name="3_12" type="revolute">
       <parent link="3"/>
       <child  link="12"/>
       <origin rpy="0 0 0" xyz="0.3539102513801054 -0.2556104385896699 0.0" />
     <axis xyz="1 0 0"/>
       <limit effort="0.0" lower="-3.14159" upper="3.14159" velocity="0.0"/>
    </joint>
</robot>