<robot name = "robot">
    <link name="root">
        <inertial>
            <origin xyz="0 0 2.0" rpy="0 0 0"/>
            <mass value="1" />
            <inertia ixx="100" ixy="0" ixz="0" iyy="100" iyz="0" izz="100" />
        </inertial>
        <visual>
            <origin xyz="0 0 2.0" rpy="0 0 0"/>
            <geometry>
                <box size="0.996350436832409 0.7594021253667071 0.5861398507385627" />
            </geometry>
            <material name="0 0 1 1">
                <color rgba="0 0 1 1"/>
            </material>
        </visual>
        <collision>
            <origin xyz="0 0 2.0" rpy="0 0 0"/>
            <geometry>
                <box size="0.996350436832409 0.7594021253667071 0.5861398507385627" />
            </geometry>
        </collision>
    </link>
    <link name="0">
        <inertial>
            <origin xyz="0.0 0.0 -0.3154999261798339" rpy="0 0 0"/>
            <mass value="1" />
            <inertia ixx="100" ixy="0" ixz="0" iyy="100" iyz="0" izz="100" />
        </inertial>
        <visual>
            <origin xyz="0.0 0.0 -0.3154999261798339" rpy="0 0 0"/>
            <geometry>
                <box size="0.7435969545367118 0.7099967760051205 0.6309998523596678" />
            </geometry>
            <material name="0 0 1 1">
                <color rgba="0 0 1 1"/>
            </material>
        </visual>
        <collision>
            <origin xyz="0.0 0.0 -0.3154999261798339" rpy="0 0 0"/>
            <geometry>
                <box size="0.7435969545367118 0.7099967760051205 0.6309998523596678" />
            </geometry>
        </collision>
    </link>
    <link name="1">
        <inertial>
            <origin xyz="0.30085845609252265 0.0 0.0" rpy="0 0 0"/>
            <mass value="1" />
            <inertia ixx="100" ixy="0" ixz="0" iyy="100" iyz="0" izz="100" />
        </inertial>
        <visual>
            <origin xyz="0.30085845609252265 0.0 0.0" rpy="0 0 0"/>
            <geometry>
                <box size="0.6017169121850453 0.9481612784020024 0.9365471891348203" />
            </geometry>
            <material name="0 1 0 1">
                <color rgba="0 1 0 1"/>
            </material>
        </visual>
        <collision>
            <origin xyz="0.30085845609252265 0.0 0.0" rpy="0 0 0"/>
            <geometry>
                <box size="0.6017169121850453 0.9481612784020024 0.9365471891348203" />
            </geometry>
        </collision>
    </link>
    <link name="2">
        <inertial>
            <origin xyz="0.0 0.45924944555337804 0.0" rpy="0 0 0"/>
            <mass value="1" />
            <inertia ixx="100" ixy="0" ixz="0" iyy="100" iyz="0" izz="100" />
        </inertial>
        <visual>
            <origin xyz="0.0 0.45924944555337804 0.0" rpy="0 0 0"/>
            <geometry>
                <box size="0.5590963146735193 0.9184988911067561 0.8720679606847677" />
            </geometry>
            <material name="0 1 0 1">
                <color rgba="0 1 0 1"/>
            </material>
        </visual>
        <collision>
            <origin xyz="0.0 0.45924944555337804 0.0" rpy="0 0 0"/>
            <geometry>
                <box size="0.5590963146735193 0.9184988911067561 0.8720679606847677" />
            </geometry>
        </collision>
    </link>
    <link name="3">
        <inertial>
            <origin xyz="0.0 0.0 0.31106666580224396" rpy="0 0 0"/>
            <mass value="1" />
            <inertia ixx="100" ixy="0" ixz="0" iyy="100" iyz="0" izz="100" />
        </inertial>
        <visual>
            <origin xyz="0.0 0.0 0.31106666580224396" rpy="0 0 0"/>
            <geometry>
                <box size="0.6910503212745698 0.5633566919234614 0.6221333316044879" />
            </geometry>
            <material name="0 0 1 1">
                <color rgba="0 0 1 1"/>
            </material>
        </visual>
        <collision>
            <origin xyz="0.0 0.0 0.31106666580224396" rpy="0 0 0"/>
            <geometry>
                <box size="0.6910503212745698 0.5633566919234614 0.6221333316044879" />
            </geometry>
        </collision>
    </link>
    <link name="4">
        <inertial>
            <origin xyz="0.0 0.29862782128072796 0.0" rpy="0 0 0"/>
            <mass value="1" />
            <inertia ixx="100" ixy="0" ixz="0" iyy="100" iyz="0" izz="100" />
        </inertial>
        <visual>
            <origin xyz="0.0 0.29862782128072796 0.0" rpy="0 0 0"/>
            <geometry>
                <box size="0.9433730061865055 0.5972556425614559 0.7149025258849349" />
            </geometry>
            <material name="0 0 1 1">
                <color rgba="0 0 1 1"/>
            </material>
        </visual>
        <collision>
            <origin xyz="0.0 0.29862782128072796 0.0" rpy="0 0 0"/>
            <geometry>
                <box size="0.9433730061865055 0.5972556425614559 0.7149025258849349" />
            </geometry>
        </collision>
    </link>
    <link name="5">
        <inertial>
            <origin xyz="-0.4011408141495359 0.0 0.0" rpy="0 0 0"/>
            <mass value="1" />
            <inertia ixx="100" ixy="0" ixz="0" iyy="100" iyz="0" izz="100" />
        </inertial>
        <visual>
            <origin xyz="-0.4011408141495359 0.0 0.0" rpy="0 0 0"/>
            <geometry>
                <box size="0.8022816282990718 0.7755659618118593 0.8750765721289209" />
            </geometry>
            <material name="0 0 1 1">
                <color rgba="0 0 1 1"/>
            </material>
        </visual>
        <collision>
            <origin xyz="-0.4011408141495359 0.0 0.0" rpy="0 0 0"/>
            <geometry>
                <box size="0.8022816282990718 0.7755659618118593 0.8750765721289209" />
            </geometry>
        </collision>
    </link>
    <link name="6">
        <inertial>
            <origin xyz="-0.30373175586388507 0.0 0.0" rpy="0 0 0"/>
            <mass value="1" />
            <inertia ixx="100" ixy="0" ixz="0" iyy="100" iyz="0" izz="100" />
        </inertial>
        <visual>
            <origin xyz="-0.30373175586388507 0.0 0.0" rpy="0 0 0"/>
            <geometry>
                <box size="0.6074635117277701 0.8902115543282348 0.9743433912068795" />
            </geometry>
            <material name="0 1 0 1">
                <color rgba="0 1 0 1"/>
            </material>
        </visual>
        <collision>
            <origin xyz="-0.30373175586388507 0.0 0.0" rpy="0 0 0"/>
            <geometry>
                <box size="0.6074635117277701 0.8902115543282348 0.9743433912068795" />
            </geometry>
        </collision>
    </link>
    <link name="7">
        <inertial>
            <origin xyz="-0.48372753594541873 0.0 0.0" rpy="0 0 0"/>
            <mass value="1" />
            <inertia ixx="100" ixy="0" ixz="0" iyy="100" iyz="0" izz="100" />
        </inertial>
        <visual>
            <origin xyz="-0.48372753594541873 0.0 0.0" rpy="0 0 0"/>
            <geometry>
                <box size="0.9674550718908375 0.7348431421006203 0.8985943033378424" />
            </geometry>
            <material name="0 0 1 1">
                <color rgba="0 0 1 1"/>
            </material>
        </visual>
        <collision>
            <origin xyz="-0.48372753594541873 0.0 0.0" rpy="0 0 0"/>
            <geometry>
                <box size="0.9674550718908375 0.7348431421006203 0.8985943033378424" />
            </geometry>
        </collision>
    </link>
    <joint name="root_0" type="revolute">
       <parent link="root"/>
       <child  link="0"/>
       <origin rpy="0 0 0" xyz="0.0 0.0 1.7069300746307188" />
     <axis xyz="0 1 0"/>
       <limit effort="0.0" lower="-3.14159" upper="3.14159" velocity="0.0"/>
    </joint>
    <joint name="root_1" type="revolute">
       <parent link="root"/>
       <child  link="1"/>
       <origin rpy="0 0 0" xyz="0.4981752184162045 0.0 2.0" />
     <axis xyz="1 0 0"/>
       <limit effort="0.0" lower="-3.14159" upper="3.14159" velocity="0.0"/>
    </joint>
    <joint name="root_2" type="revolute">
       <parent link="root"/>
       <child  link="2"/>
       <origin rpy="0 0 0" xyz="0.0 0.3797010626833536 2.0" />
     <axis xyz="1 0 0"/>
       <limit effort="0.0" lower="-3.14159" upper="3.14159" velocity="0.0"/>
    </joint>
    <joint name="root_3" type="revolute">
       <parent link="root"/>
       <child  link="3"/>
       <origin rpy="0 0 0" xyz="0.0 0.0 2.2930699253692812" />
     <axis xyz="0 1 0"/>
       <limit effort="0.0" lower="-3.14159" upper="3.14159" velocity="0.0"/>
    </joint>
    <joint name="2_4" type="revolute">
       <parent link="2"/>
       <child  link="4"/>
       <origin rpy="0 0 0" xyz="0.0 0.9184988911067561 0.0" />
     <axis xyz="0 1 0"/>
       <limit effort="0.0" lower="-3.14159" upper="3.14159" velocity="0.0"/>
    </joint>
    <joint name="4_5" type="revolute">
       <parent link="4"/>
       <child  link="5"/>
       <origin rpy="0 0 0" xyz="-0.4716865030932528 0.29862782128072796 0.0" />
     <axis xyz="1 0 0"/>
       <limit effort="0.0" lower="-3.14159" upper="3.14159" velocity="0.0"/>
    </joint>
    <joint name="5_6" type="revolute">
       <parent link="5"/>
       <child  link="6"/>
       <origin rpy="0 0 0" xyz="-0.8022816282990718 0.0 0.0" />
     <axis xyz="1 0 0"/>
       <limit effort="0.0" lower="-3.14159" upper="3.14159" velocity="0.0"/>
    </joint>
    <joint name="6_7" type="revolute">
       <parent link="6"/>
       <child  link="7"/>
       <origin rpy="0 0 0" xyz="-0.6074635117277701 0.0 0.0" />
     <axis xyz="0 0 1"/>
       <limit effort="0.0" lower="-3.14159" upper="3.14159" velocity="0.0"/>
    </joint>
</robot>